{
 "cells": [
  {
   "cell_type": "markdown",
   "metadata": {},
   "source": [
    "# Create a Siamese Network with Triplet Loss in Keras"
   ]
  },
  {
   "cell_type": "markdown",
   "metadata": {},
   "source": [
    "# Task 1: Understanding the Approach"
   ]
  },
  {
   "cell_type": "code",
   "execution_count": null,
   "metadata": {},
   "outputs": [
    {
     "name": "stderr",
     "output_type": "stream",
     "text": [
      "ERROR:root:Internal Python error in the inspect module.\n",
      "Below is the traceback from this internal error.\n",
      "\n",
      "ERROR:root:Internal Python error in the inspect module.\n",
      "Below is the traceback from this internal error.\n",
      "\n",
      "ERROR:root:Internal Python error in the inspect module.\n",
      "Below is the traceback from this internal error.\n",
      "\n"
     ]
    },
    {
     "name": "stdout",
     "output_type": "stream",
     "text": [
      "Traceback (most recent call last):\n",
      "  File \"C:\\ProgramData\\Anaconda3\\envs\\tf\\lib\\site-packages\\IPython\\core\\interactiveshell.py\", line 3417, in run_code\n",
      "    exec(code_obj, self.user_global_ns, self.user_ns)\n",
      "  File \"<ipython-input-1-aae5fec5c951>\", line 3, in <module>\n",
      "    import tensorflow as tf\n",
      "  File \"C:\\ProgramData\\Anaconda3\\envs\\tf\\lib\\site-packages\\tensorflow\\__init__.py\", line 102, in <module>\n",
      "    from tensorflow.python.util import deprecation_wrapper as _deprecation\n",
      "  File \"C:\\ProgramData\\Anaconda3\\envs\\tf\\lib\\site-packages\\tensorflow_core\\python\\util\\deprecation_wrapper.py\", line 25, in <module>\n",
      "    from tensorflow.python.util import module_wrapper\n",
      "  File \"C:\\ProgramData\\Anaconda3\\envs\\tf\\lib\\site-packages\\tensorflow_core\\python\\util\\module_wrapper.py\", line 25, in <module>\n",
      "    from tensorflow.python.platform import tf_logging as logging\n",
      "  File \"C:\\ProgramData\\Anaconda3\\envs\\tf\\lib\\site-packages\\tensorflow_core\\python\\platform\\tf_logging.py\", line 38, in <module>\n",
      "    from tensorflow.python.util.tf_export import tf_export\n",
      "  File \"C:\\ProgramData\\Anaconda3\\envs\\tf\\lib\\site-packages\\tensorflow_core\\python\\util\\tf_export.py\", line 48, in <module>\n",
      "    from tensorflow.python.util import tf_decorator\n",
      "  File \"C:\\ProgramData\\Anaconda3\\envs\\tf\\lib\\site-packages\\tensorflow_core\\python\\util\\tf_decorator.py\", line 64, in <module>\n",
      "    from tensorflow.python.util import tf_stack\n",
      "  File \"C:\\ProgramData\\Anaconda3\\envs\\tf\\lib\\site-packages\\tensorflow_core\\python\\util\\tf_stack.py\", line 29, in <module>\n",
      "    from tensorflow.python import _tf_stack\n",
      "ImportError: cannot import name '_tf_stack' from 'tensorflow_core.python' (unknown location)\n",
      "\n",
      "During handling of the above exception, another exception occurred:\n",
      "\n",
      "Traceback (most recent call last):\n",
      "  File \"C:\\ProgramData\\Anaconda3\\envs\\tf\\lib\\site-packages\\IPython\\core\\interactiveshell.py\", line 2044, in showtraceback\n",
      "    stb = value._render_traceback_()\n",
      "AttributeError: 'ImportError' object has no attribute '_render_traceback_'\n",
      "\n",
      "During handling of the above exception, another exception occurred:\n",
      "\n",
      "Traceback (most recent call last):\n",
      "  File \"C:\\ProgramData\\Anaconda3\\envs\\tf\\lib\\site-packages\\IPython\\core\\ultratb.py\", line 1169, in get_records\n",
      "    return _fixed_getinnerframes(etb, number_of_lines_of_context, tb_offset)\n",
      "  File \"C:\\ProgramData\\Anaconda3\\envs\\tf\\lib\\site-packages\\IPython\\core\\ultratb.py\", line 316, in wrapped\n",
      "    return f(*args, **kwargs)\n",
      "  File \"C:\\ProgramData\\Anaconda3\\envs\\tf\\lib\\site-packages\\IPython\\core\\ultratb.py\", line 350, in _fixed_getinnerframes\n",
      "    records = fix_frame_records_filenames(inspect.getinnerframes(etb, context))\n",
      "  File \"C:\\ProgramData\\Anaconda3\\envs\\tf\\lib\\inspect.py\", line 1500, in getinnerframes\n",
      "    frameinfo = (tb.tb_frame,) + getframeinfo(tb, context)\n",
      "  File \"C:\\ProgramData\\Anaconda3\\envs\\tf\\lib\\inspect.py\", line 1458, in getframeinfo\n",
      "    filename = getsourcefile(frame) or getfile(frame)\n",
      "  File \"C:\\ProgramData\\Anaconda3\\envs\\tf\\lib\\inspect.py\", line 696, in getsourcefile\n",
      "    if getattr(getmodule(object, filename), '__loader__', None) is not None:\n",
      "  File \"C:\\ProgramData\\Anaconda3\\envs\\tf\\lib\\inspect.py\", line 733, in getmodule\n",
      "    if ismodule(module) and hasattr(module, '__file__'):\n",
      "  File \"C:\\ProgramData\\Anaconda3\\envs\\tf\\lib\\site-packages\\tensorflow\\__init__.py\", line 50, in __getattr__\n",
      "    module = self._load()\n",
      "  File \"C:\\ProgramData\\Anaconda3\\envs\\tf\\lib\\site-packages\\tensorflow\\__init__.py\", line 44, in _load\n",
      "    module = _importlib.import_module(self.__name__)\n",
      "  File \"C:\\ProgramData\\Anaconda3\\envs\\tf\\lib\\importlib\\__init__.py\", line 127, in import_module\n",
      "    return _bootstrap._gcd_import(name[level:], package, level)\n",
      "  File \"<frozen importlib._bootstrap>\", line 1006, in _gcd_import\n",
      "  File \"<frozen importlib._bootstrap>\", line 983, in _find_and_load\n",
      "  File \"<frozen importlib._bootstrap>\", line 965, in _find_and_load_unlocked\n",
      "ModuleNotFoundError: No module named 'tensorflow_core._api'\n",
      "Traceback (most recent call last):\n",
      "  File \"C:\\ProgramData\\Anaconda3\\envs\\tf\\lib\\site-packages\\IPython\\core\\interactiveshell.py\", line 3417, in run_code\n",
      "    exec(code_obj, self.user_global_ns, self.user_ns)\n",
      "  File \"<ipython-input-1-aae5fec5c951>\", line 3, in <module>\n",
      "    import tensorflow as tf\n",
      "  File \"C:\\ProgramData\\Anaconda3\\envs\\tf\\lib\\site-packages\\tensorflow\\__init__.py\", line 102, in <module>\n",
      "    from tensorflow.python.util import deprecation_wrapper as _deprecation\n",
      "  File \"C:\\ProgramData\\Anaconda3\\envs\\tf\\lib\\site-packages\\tensorflow_core\\python\\util\\deprecation_wrapper.py\", line 25, in <module>\n",
      "    from tensorflow.python.util import module_wrapper\n",
      "  File \"C:\\ProgramData\\Anaconda3\\envs\\tf\\lib\\site-packages\\tensorflow_core\\python\\util\\module_wrapper.py\", line 25, in <module>\n",
      "    from tensorflow.python.platform import tf_logging as logging\n",
      "  File \"C:\\ProgramData\\Anaconda3\\envs\\tf\\lib\\site-packages\\tensorflow_core\\python\\platform\\tf_logging.py\", line 38, in <module>\n",
      "    from tensorflow.python.util.tf_export import tf_export\n",
      "  File \"C:\\ProgramData\\Anaconda3\\envs\\tf\\lib\\site-packages\\tensorflow_core\\python\\util\\tf_export.py\", line 48, in <module>\n",
      "    from tensorflow.python.util import tf_decorator\n",
      "  File \"C:\\ProgramData\\Anaconda3\\envs\\tf\\lib\\site-packages\\tensorflow_core\\python\\util\\tf_decorator.py\", line 64, in <module>\n",
      "    from tensorflow.python.util import tf_stack\n",
      "  File \"C:\\ProgramData\\Anaconda3\\envs\\tf\\lib\\site-packages\\tensorflow_core\\python\\util\\tf_stack.py\", line 29, in <module>\n",
      "    from tensorflow.python import _tf_stack\n",
      "ImportError: cannot import name '_tf_stack' from 'tensorflow_core.python' (unknown location)\n",
      "\n",
      "During handling of the above exception, another exception occurred:\n",
      "\n",
      "Traceback (most recent call last):\n",
      "  File \"C:\\ProgramData\\Anaconda3\\envs\\tf\\lib\\site-packages\\IPython\\core\\interactiveshell.py\", line 2044, in showtraceback\n",
      "    stb = value._render_traceback_()\n",
      "AttributeError: 'ImportError' object has no attribute '_render_traceback_'\n",
      "\n",
      "During handling of the above exception, another exception occurred:\n",
      "\n",
      "Traceback (most recent call last):\n",
      "  File \"C:\\ProgramData\\Anaconda3\\envs\\tf\\lib\\site-packages\\IPython\\core\\interactiveshell.py\", line 3337, in run_ast_nodes\n",
      "    if (await self.run_code(code, result,  async_=asy)):\n",
      "  File \"C:\\ProgramData\\Anaconda3\\envs\\tf\\lib\\site-packages\\IPython\\core\\interactiveshell.py\", line 3434, in run_code\n",
      "    self.showtraceback(running_compiled_code=True)\n",
      "  File \"C:\\ProgramData\\Anaconda3\\envs\\tf\\lib\\site-packages\\IPython\\core\\interactiveshell.py\", line 2047, in showtraceback\n",
      "    value, tb, tb_offset=tb_offset)\n",
      "  File \"C:\\ProgramData\\Anaconda3\\envs\\tf\\lib\\site-packages\\IPython\\core\\ultratb.py\", line 1436, in structured_traceback\n",
      "    self, etype, value, tb, tb_offset, number_of_lines_of_context)\n",
      "  File \"C:\\ProgramData\\Anaconda3\\envs\\tf\\lib\\site-packages\\IPython\\core\\ultratb.py\", line 1336, in structured_traceback\n",
      "    self, etype, value, tb, tb_offset, number_of_lines_of_context\n",
      "  File \"C:\\ProgramData\\Anaconda3\\envs\\tf\\lib\\site-packages\\IPython\\core\\ultratb.py\", line 1193, in structured_traceback\n",
      "    tb_offset)\n",
      "  File \"C:\\ProgramData\\Anaconda3\\envs\\tf\\lib\\site-packages\\IPython\\core\\ultratb.py\", line 1150, in format_exception_as_a_whole\n",
      "    last_unique, recursion_repeat = find_recursion(orig_etype, evalue, records)\n",
      "  File \"C:\\ProgramData\\Anaconda3\\envs\\tf\\lib\\site-packages\\IPython\\core\\ultratb.py\", line 451, in find_recursion\n",
      "    return len(records), 0\n",
      "TypeError: object of type 'NoneType' has no len()\n",
      "\n",
      "During handling of the above exception, another exception occurred:\n",
      "\n",
      "Traceback (most recent call last):\n",
      "  File \"C:\\ProgramData\\Anaconda3\\envs\\tf\\lib\\site-packages\\IPython\\core\\interactiveshell.py\", line 2044, in showtraceback\n",
      "    stb = value._render_traceback_()\n",
      "AttributeError: 'TypeError' object has no attribute '_render_traceback_'\n",
      "\n",
      "During handling of the above exception, another exception occurred:\n",
      "\n",
      "Traceback (most recent call last):\n",
      "  File \"C:\\ProgramData\\Anaconda3\\envs\\tf\\lib\\site-packages\\IPython\\core\\ultratb.py\", line 1169, in get_records\n",
      "    return _fixed_getinnerframes(etb, number_of_lines_of_context, tb_offset)\n",
      "  File \"C:\\ProgramData\\Anaconda3\\envs\\tf\\lib\\site-packages\\IPython\\core\\ultratb.py\", line 316, in wrapped\n",
      "    return f(*args, **kwargs)\n",
      "  File \"C:\\ProgramData\\Anaconda3\\envs\\tf\\lib\\site-packages\\IPython\\core\\ultratb.py\", line 350, in _fixed_getinnerframes\n",
      "    records = fix_frame_records_filenames(inspect.getinnerframes(etb, context))\n",
      "  File \"C:\\ProgramData\\Anaconda3\\envs\\tf\\lib\\inspect.py\", line 1500, in getinnerframes\n",
      "    frameinfo = (tb.tb_frame,) + getframeinfo(tb, context)\n",
      "  File \"C:\\ProgramData\\Anaconda3\\envs\\tf\\lib\\inspect.py\", line 1458, in getframeinfo\n",
      "    filename = getsourcefile(frame) or getfile(frame)\n",
      "  File \"C:\\ProgramData\\Anaconda3\\envs\\tf\\lib\\inspect.py\", line 696, in getsourcefile\n",
      "    if getattr(getmodule(object, filename), '__loader__', None) is not None:\n",
      "  File \"C:\\ProgramData\\Anaconda3\\envs\\tf\\lib\\inspect.py\", line 733, in getmodule\n",
      "    if ismodule(module) and hasattr(module, '__file__'):\n",
      "  File \"C:\\ProgramData\\Anaconda3\\envs\\tf\\lib\\site-packages\\tensorflow\\__init__.py\", line 50, in __getattr__\n",
      "    module = self._load()\n",
      "  File \"C:\\ProgramData\\Anaconda3\\envs\\tf\\lib\\site-packages\\tensorflow\\__init__.py\", line 44, in _load\n",
      "    module = _importlib.import_module(self.__name__)\n",
      "  File \"C:\\ProgramData\\Anaconda3\\envs\\tf\\lib\\importlib\\__init__.py\", line 127, in import_module\n",
      "    return _bootstrap._gcd_import(name[level:], package, level)\n",
      "  File \"<frozen importlib._bootstrap>\", line 1006, in _gcd_import\n",
      "  File \"<frozen importlib._bootstrap>\", line 983, in _find_and_load\n",
      "  File \"<frozen importlib._bootstrap>\", line 965, in _find_and_load_unlocked\n",
      "ModuleNotFoundError: No module named 'tensorflow_core._api'\n",
      "ERROR! Session/line number was not unique in database. History logging moved to new session 1027\n",
      "Traceback (most recent call last):\n",
      "  File \"C:\\ProgramData\\Anaconda3\\envs\\tf\\lib\\site-packages\\IPython\\core\\interactiveshell.py\", line 3417, in run_code\n",
      "    exec(code_obj, self.user_global_ns, self.user_ns)\n",
      "  File \"<ipython-input-1-aae5fec5c951>\", line 3, in <module>\n",
      "    import tensorflow as tf\n",
      "  File \"C:\\ProgramData\\Anaconda3\\envs\\tf\\lib\\site-packages\\tensorflow\\__init__.py\", line 102, in <module>\n",
      "    from tensorflow.python.util import deprecation_wrapper as _deprecation\n",
      "  File \"C:\\ProgramData\\Anaconda3\\envs\\tf\\lib\\site-packages\\tensorflow_core\\python\\util\\deprecation_wrapper.py\", line 25, in <module>\n",
      "    from tensorflow.python.util import module_wrapper\n",
      "  File \"C:\\ProgramData\\Anaconda3\\envs\\tf\\lib\\site-packages\\tensorflow_core\\python\\util\\module_wrapper.py\", line 25, in <module>\n",
      "    from tensorflow.python.platform import tf_logging as logging\n",
      "  File \"C:\\ProgramData\\Anaconda3\\envs\\tf\\lib\\site-packages\\tensorflow_core\\python\\platform\\tf_logging.py\", line 38, in <module>\n",
      "    from tensorflow.python.util.tf_export import tf_export\n",
      "  File \"C:\\ProgramData\\Anaconda3\\envs\\tf\\lib\\site-packages\\tensorflow_core\\python\\util\\tf_export.py\", line 48, in <module>\n",
      "    from tensorflow.python.util import tf_decorator\n",
      "  File \"C:\\ProgramData\\Anaconda3\\envs\\tf\\lib\\site-packages\\tensorflow_core\\python\\util\\tf_decorator.py\", line 64, in <module>\n",
      "    from tensorflow.python.util import tf_stack\n",
      "  File \"C:\\ProgramData\\Anaconda3\\envs\\tf\\lib\\site-packages\\tensorflow_core\\python\\util\\tf_stack.py\", line 29, in <module>\n",
      "    from tensorflow.python import _tf_stack\n",
      "ImportError: cannot import name '_tf_stack' from 'tensorflow_core.python' (unknown location)\n",
      "\n",
      "During handling of the above exception, another exception occurred:\n",
      "\n",
      "Traceback (most recent call last):\n",
      "  File \"C:\\ProgramData\\Anaconda3\\envs\\tf\\lib\\site-packages\\IPython\\core\\interactiveshell.py\", line 2044, in showtraceback\n",
      "    stb = value._render_traceback_()\n",
      "AttributeError: 'ImportError' object has no attribute '_render_traceback_'\n",
      "\n",
      "During handling of the above exception, another exception occurred:\n",
      "\n",
      "Traceback (most recent call last):\n",
      "  File \"C:\\ProgramData\\Anaconda3\\envs\\tf\\lib\\site-packages\\IPython\\core\\interactiveshell.py\", line 3337, in run_ast_nodes\n",
      "    if (await self.run_code(code, result,  async_=asy)):\n",
      "  File \"C:\\ProgramData\\Anaconda3\\envs\\tf\\lib\\site-packages\\IPython\\core\\interactiveshell.py\", line 3434, in run_code\n",
      "    self.showtraceback(running_compiled_code=True)\n",
      "  File \"C:\\ProgramData\\Anaconda3\\envs\\tf\\lib\\site-packages\\IPython\\core\\interactiveshell.py\", line 2047, in showtraceback\n",
      "    value, tb, tb_offset=tb_offset)\n",
      "  File \"C:\\ProgramData\\Anaconda3\\envs\\tf\\lib\\site-packages\\IPython\\core\\ultratb.py\", line 1436, in structured_traceback\n",
      "    self, etype, value, tb, tb_offset, number_of_lines_of_context)\n",
      "  File \"C:\\ProgramData\\Anaconda3\\envs\\tf\\lib\\site-packages\\IPython\\core\\ultratb.py\", line 1336, in structured_traceback\n",
      "    self, etype, value, tb, tb_offset, number_of_lines_of_context\n",
      "  File \"C:\\ProgramData\\Anaconda3\\envs\\tf\\lib\\site-packages\\IPython\\core\\ultratb.py\", line 1193, in structured_traceback\n",
      "    tb_offset)\n",
      "  File \"C:\\ProgramData\\Anaconda3\\envs\\tf\\lib\\site-packages\\IPython\\core\\ultratb.py\", line 1150, in format_exception_as_a_whole\n",
      "    last_unique, recursion_repeat = find_recursion(orig_etype, evalue, records)\n",
      "  File \"C:\\ProgramData\\Anaconda3\\envs\\tf\\lib\\site-packages\\IPython\\core\\ultratb.py\", line 451, in find_recursion\n",
      "    return len(records), 0\n",
      "TypeError: object of type 'NoneType' has no len()\n",
      "\n",
      "During handling of the above exception, another exception occurred:\n",
      "\n",
      "Traceback (most recent call last):\n",
      "  File \"C:\\ProgramData\\Anaconda3\\envs\\tf\\lib\\site-packages\\IPython\\core\\interactiveshell.py\", line 2044, in showtraceback\n",
      "    stb = value._render_traceback_()\n",
      "AttributeError: 'TypeError' object has no attribute '_render_traceback_'\n",
      "\n",
      "During handling of the above exception, another exception occurred:\n",
      "\n",
      "Traceback (most recent call last):\n",
      "  File \"C:\\ProgramData\\Anaconda3\\envs\\tf\\lib\\site-packages\\IPython\\core\\interactiveshell.py\", line 2922, in _run_cell\n",
      "    return runner(coro)\n",
      "  File \"C:\\ProgramData\\Anaconda3\\envs\\tf\\lib\\site-packages\\IPython\\core\\async_helpers.py\", line 68, in _pseudo_sync_runner\n",
      "    coro.send(None)\n",
      "  File \"C:\\ProgramData\\Anaconda3\\envs\\tf\\lib\\site-packages\\IPython\\core\\interactiveshell.py\", line 3146, in run_cell_async\n",
      "    interactivity=interactivity, compiler=compiler, result=result)\n",
      "  File \"C:\\ProgramData\\Anaconda3\\envs\\tf\\lib\\site-packages\\IPython\\core\\interactiveshell.py\", line 3356, in run_ast_nodes\n",
      "    self.showtraceback()\n",
      "  File \"C:\\ProgramData\\Anaconda3\\envs\\tf\\lib\\site-packages\\IPython\\core\\interactiveshell.py\", line 2047, in showtraceback\n",
      "    value, tb, tb_offset=tb_offset)\n",
      "  File \"C:\\ProgramData\\Anaconda3\\envs\\tf\\lib\\site-packages\\IPython\\core\\ultratb.py\", line 1436, in structured_traceback\n",
      "    self, etype, value, tb, tb_offset, number_of_lines_of_context)\n",
      "  File \"C:\\ProgramData\\Anaconda3\\envs\\tf\\lib\\site-packages\\IPython\\core\\ultratb.py\", line 1336, in structured_traceback\n",
      "    self, etype, value, tb, tb_offset, number_of_lines_of_context\n",
      "  File \"C:\\ProgramData\\Anaconda3\\envs\\tf\\lib\\site-packages\\IPython\\core\\ultratb.py\", line 1211, in structured_traceback\n",
      "    chained_exceptions_tb_offset)\n",
      "  File \"C:\\ProgramData\\Anaconda3\\envs\\tf\\lib\\site-packages\\IPython\\core\\ultratb.py\", line 1150, in format_exception_as_a_whole\n",
      "    last_unique, recursion_repeat = find_recursion(orig_etype, evalue, records)\n",
      "  File \"C:\\ProgramData\\Anaconda3\\envs\\tf\\lib\\site-packages\\IPython\\core\\ultratb.py\", line 451, in find_recursion\n",
      "    return len(records), 0\n",
      "TypeError: object of type 'NoneType' has no len()\n",
      "\n",
      "During handling of the above exception, another exception occurred:\n",
      "\n",
      "Traceback (most recent call last):\n",
      "  File \"C:\\ProgramData\\Anaconda3\\envs\\tf\\lib\\site-packages\\IPython\\core\\interactiveshell.py\", line 2044, in showtraceback\n",
      "    stb = value._render_traceback_()\n",
      "AttributeError: 'TypeError' object has no attribute '_render_traceback_'\n",
      "\n",
      "During handling of the above exception, another exception occurred:\n",
      "\n",
      "Traceback (most recent call last):\n",
      "  File \"C:\\ProgramData\\Anaconda3\\envs\\tf\\lib\\site-packages\\IPython\\core\\ultratb.py\", line 1169, in get_records\n",
      "    return _fixed_getinnerframes(etb, number_of_lines_of_context, tb_offset)\n",
      "  File \"C:\\ProgramData\\Anaconda3\\envs\\tf\\lib\\site-packages\\IPython\\core\\ultratb.py\", line 316, in wrapped\n",
      "    return f(*args, **kwargs)\n",
      "  File \"C:\\ProgramData\\Anaconda3\\envs\\tf\\lib\\site-packages\\IPython\\core\\ultratb.py\", line 350, in _fixed_getinnerframes\n",
      "    records = fix_frame_records_filenames(inspect.getinnerframes(etb, context))\n",
      "  File \"C:\\ProgramData\\Anaconda3\\envs\\tf\\lib\\inspect.py\", line 1500, in getinnerframes\n",
      "    frameinfo = (tb.tb_frame,) + getframeinfo(tb, context)\n",
      "  File \"C:\\ProgramData\\Anaconda3\\envs\\tf\\lib\\inspect.py\", line 1458, in getframeinfo\n",
      "    filename = getsourcefile(frame) or getfile(frame)\n",
      "  File \"C:\\ProgramData\\Anaconda3\\envs\\tf\\lib\\inspect.py\", line 696, in getsourcefile\n",
      "    if getattr(getmodule(object, filename), '__loader__', None) is not None:\n",
      "  File \"C:\\ProgramData\\Anaconda3\\envs\\tf\\lib\\inspect.py\", line 733, in getmodule\n",
      "    if ismodule(module) and hasattr(module, '__file__'):\n",
      "  File \"C:\\ProgramData\\Anaconda3\\envs\\tf\\lib\\site-packages\\tensorflow\\__init__.py\", line 50, in __getattr__\n",
      "    module = self._load()\n",
      "  File \"C:\\ProgramData\\Anaconda3\\envs\\tf\\lib\\site-packages\\tensorflow\\__init__.py\", line 44, in _load\n",
      "    module = _importlib.import_module(self.__name__)\n",
      "  File \"C:\\ProgramData\\Anaconda3\\envs\\tf\\lib\\importlib\\__init__.py\", line 127, in import_module\n",
      "    return _bootstrap._gcd_import(name[level:], package, level)\n",
      "  File \"<frozen importlib._bootstrap>\", line 1006, in _gcd_import\n",
      "  File \"<frozen importlib._bootstrap>\", line 983, in _find_and_load\n",
      "  File \"<frozen importlib._bootstrap>\", line 965, in _find_and_load_unlocked\n",
      "ModuleNotFoundError: No module named 'tensorflow_core._api'\n"
     ]
    }
   ],
   "source": [
    "%matplotlib notebook\n",
    "\n",
    "import tensorflow as tf\n",
    "import matplotlib.pyplot as plt\n",
    "import numpy as np\n",
    "import random\n",
    "\n",
    "from pca_plotter import PCAPlotter\n",
    "\n",
    "print('TensorFlow version:', tf.__version__)"
   ]
  },
  {
   "cell_type": "code",
   "execution_count": null,
   "metadata": {},
   "outputs": [
    {
     "name": "stderr",
     "output_type": "stream",
     "text": [
      "ERROR:root:Internal Python error in the inspect module.\n",
      "Below is the traceback from this internal error.\n",
      "\n",
      "ERROR:root:Internal Python error in the inspect module.\n",
      "Below is the traceback from this internal error.\n",
      "\n",
      "ERROR:root:Internal Python error in the inspect module.\n",
      "Below is the traceback from this internal error.\n",
      "\n"
     ]
    },
    {
     "name": "stdout",
     "output_type": "stream",
     "text": [
      "Traceback (most recent call last):\n",
      "  File \"C:\\ProgramData\\Anaconda3\\envs\\tf\\lib\\site-packages\\IPython\\core\\interactiveshell.py\", line 3417, in run_code\n",
      "    exec(code_obj, self.user_global_ns, self.user_ns)\n",
      "  File \"<ipython-input-1-64156d691fe5>\", line 1, in <module>\n",
      "    import tensorflow as tf\n",
      "  File \"C:\\ProgramData\\Anaconda3\\envs\\tf\\lib\\site-packages\\tensorflow\\__init__.py\", line 102, in <module>\n",
      "    from tensorflow.python.util import deprecation_wrapper as _deprecation\n",
      "  File \"C:\\ProgramData\\Anaconda3\\envs\\tf\\lib\\site-packages\\tensorflow_core\\python\\util\\deprecation_wrapper.py\", line 25, in <module>\n",
      "    from tensorflow.python.util import module_wrapper\n",
      "  File \"C:\\ProgramData\\Anaconda3\\envs\\tf\\lib\\site-packages\\tensorflow_core\\python\\util\\module_wrapper.py\", line 25, in <module>\n",
      "    from tensorflow.python.platform import tf_logging as logging\n",
      "  File \"C:\\ProgramData\\Anaconda3\\envs\\tf\\lib\\site-packages\\tensorflow_core\\python\\platform\\tf_logging.py\", line 38, in <module>\n",
      "    from tensorflow.python.util.tf_export import tf_export\n",
      "  File \"C:\\ProgramData\\Anaconda3\\envs\\tf\\lib\\site-packages\\tensorflow_core\\python\\util\\tf_export.py\", line 48, in <module>\n",
      "    from tensorflow.python.util import tf_decorator\n",
      "  File \"C:\\ProgramData\\Anaconda3\\envs\\tf\\lib\\site-packages\\tensorflow_core\\python\\util\\tf_decorator.py\", line 64, in <module>\n",
      "    from tensorflow.python.util import tf_stack\n",
      "  File \"C:\\ProgramData\\Anaconda3\\envs\\tf\\lib\\site-packages\\tensorflow_core\\python\\util\\tf_stack.py\", line 29, in <module>\n",
      "    from tensorflow.python import _tf_stack\n",
      "ImportError: cannot import name '_tf_stack' from 'tensorflow_core.python' (unknown location)\n",
      "\n",
      "During handling of the above exception, another exception occurred:\n",
      "\n",
      "Traceback (most recent call last):\n",
      "  File \"C:\\ProgramData\\Anaconda3\\envs\\tf\\lib\\site-packages\\IPython\\core\\interactiveshell.py\", line 2044, in showtraceback\n",
      "    stb = value._render_traceback_()\n",
      "AttributeError: 'ImportError' object has no attribute '_render_traceback_'\n",
      "\n",
      "During handling of the above exception, another exception occurred:\n",
      "\n",
      "Traceback (most recent call last):\n",
      "  File \"C:\\ProgramData\\Anaconda3\\envs\\tf\\lib\\site-packages\\IPython\\core\\ultratb.py\", line 1169, in get_records\n",
      "    return _fixed_getinnerframes(etb, number_of_lines_of_context, tb_offset)\n",
      "  File \"C:\\ProgramData\\Anaconda3\\envs\\tf\\lib\\site-packages\\IPython\\core\\ultratb.py\", line 316, in wrapped\n",
      "    return f(*args, **kwargs)\n",
      "  File \"C:\\ProgramData\\Anaconda3\\envs\\tf\\lib\\site-packages\\IPython\\core\\ultratb.py\", line 350, in _fixed_getinnerframes\n",
      "    records = fix_frame_records_filenames(inspect.getinnerframes(etb, context))\n",
      "  File \"C:\\ProgramData\\Anaconda3\\envs\\tf\\lib\\inspect.py\", line 1500, in getinnerframes\n",
      "    frameinfo = (tb.tb_frame,) + getframeinfo(tb, context)\n",
      "  File \"C:\\ProgramData\\Anaconda3\\envs\\tf\\lib\\inspect.py\", line 1458, in getframeinfo\n",
      "    filename = getsourcefile(frame) or getfile(frame)\n",
      "  File \"C:\\ProgramData\\Anaconda3\\envs\\tf\\lib\\inspect.py\", line 696, in getsourcefile\n",
      "    if getattr(getmodule(object, filename), '__loader__', None) is not None:\n",
      "  File \"C:\\ProgramData\\Anaconda3\\envs\\tf\\lib\\inspect.py\", line 733, in getmodule\n",
      "    if ismodule(module) and hasattr(module, '__file__'):\n",
      "  File \"C:\\ProgramData\\Anaconda3\\envs\\tf\\lib\\site-packages\\tensorflow\\__init__.py\", line 50, in __getattr__\n",
      "    module = self._load()\n",
      "  File \"C:\\ProgramData\\Anaconda3\\envs\\tf\\lib\\site-packages\\tensorflow\\__init__.py\", line 44, in _load\n",
      "    module = _importlib.import_module(self.__name__)\n",
      "  File \"C:\\ProgramData\\Anaconda3\\envs\\tf\\lib\\importlib\\__init__.py\", line 127, in import_module\n",
      "    return _bootstrap._gcd_import(name[level:], package, level)\n",
      "  File \"<frozen importlib._bootstrap>\", line 1006, in _gcd_import\n",
      "  File \"<frozen importlib._bootstrap>\", line 983, in _find_and_load\n",
      "  File \"<frozen importlib._bootstrap>\", line 965, in _find_and_load_unlocked\n",
      "ModuleNotFoundError: No module named 'tensorflow_core._api'\n",
      "Traceback (most recent call last):\n",
      "  File \"C:\\ProgramData\\Anaconda3\\envs\\tf\\lib\\site-packages\\IPython\\core\\interactiveshell.py\", line 3417, in run_code\n",
      "    exec(code_obj, self.user_global_ns, self.user_ns)\n",
      "  File \"<ipython-input-1-64156d691fe5>\", line 1, in <module>\n",
      "    import tensorflow as tf\n",
      "  File \"C:\\ProgramData\\Anaconda3\\envs\\tf\\lib\\site-packages\\tensorflow\\__init__.py\", line 102, in <module>\n",
      "    from tensorflow.python.util import deprecation_wrapper as _deprecation\n",
      "  File \"C:\\ProgramData\\Anaconda3\\envs\\tf\\lib\\site-packages\\tensorflow_core\\python\\util\\deprecation_wrapper.py\", line 25, in <module>\n",
      "    from tensorflow.python.util import module_wrapper\n",
      "  File \"C:\\ProgramData\\Anaconda3\\envs\\tf\\lib\\site-packages\\tensorflow_core\\python\\util\\module_wrapper.py\", line 25, in <module>\n",
      "    from tensorflow.python.platform import tf_logging as logging\n",
      "  File \"C:\\ProgramData\\Anaconda3\\envs\\tf\\lib\\site-packages\\tensorflow_core\\python\\platform\\tf_logging.py\", line 38, in <module>\n",
      "    from tensorflow.python.util.tf_export import tf_export\n",
      "  File \"C:\\ProgramData\\Anaconda3\\envs\\tf\\lib\\site-packages\\tensorflow_core\\python\\util\\tf_export.py\", line 48, in <module>\n",
      "    from tensorflow.python.util import tf_decorator\n",
      "  File \"C:\\ProgramData\\Anaconda3\\envs\\tf\\lib\\site-packages\\tensorflow_core\\python\\util\\tf_decorator.py\", line 64, in <module>\n",
      "    from tensorflow.python.util import tf_stack\n",
      "  File \"C:\\ProgramData\\Anaconda3\\envs\\tf\\lib\\site-packages\\tensorflow_core\\python\\util\\tf_stack.py\", line 29, in <module>\n",
      "    from tensorflow.python import _tf_stack\n",
      "ImportError: cannot import name '_tf_stack' from 'tensorflow_core.python' (unknown location)\n",
      "\n",
      "During handling of the above exception, another exception occurred:\n",
      "\n",
      "Traceback (most recent call last):\n",
      "  File \"C:\\ProgramData\\Anaconda3\\envs\\tf\\lib\\site-packages\\IPython\\core\\interactiveshell.py\", line 2044, in showtraceback\n",
      "    stb = value._render_traceback_()\n",
      "AttributeError: 'ImportError' object has no attribute '_render_traceback_'\n",
      "\n",
      "During handling of the above exception, another exception occurred:\n",
      "\n",
      "Traceback (most recent call last):\n",
      "  File \"C:\\ProgramData\\Anaconda3\\envs\\tf\\lib\\site-packages\\IPython\\core\\interactiveshell.py\", line 3337, in run_ast_nodes\n",
      "    if (await self.run_code(code, result,  async_=asy)):\n",
      "  File \"C:\\ProgramData\\Anaconda3\\envs\\tf\\lib\\site-packages\\IPython\\core\\interactiveshell.py\", line 3434, in run_code\n",
      "    self.showtraceback(running_compiled_code=True)\n",
      "  File \"C:\\ProgramData\\Anaconda3\\envs\\tf\\lib\\site-packages\\IPython\\core\\interactiveshell.py\", line 2047, in showtraceback\n",
      "    value, tb, tb_offset=tb_offset)\n",
      "  File \"C:\\ProgramData\\Anaconda3\\envs\\tf\\lib\\site-packages\\IPython\\core\\ultratb.py\", line 1436, in structured_traceback\n",
      "    self, etype, value, tb, tb_offset, number_of_lines_of_context)\n",
      "  File \"C:\\ProgramData\\Anaconda3\\envs\\tf\\lib\\site-packages\\IPython\\core\\ultratb.py\", line 1336, in structured_traceback\n",
      "    self, etype, value, tb, tb_offset, number_of_lines_of_context\n",
      "  File \"C:\\ProgramData\\Anaconda3\\envs\\tf\\lib\\site-packages\\IPython\\core\\ultratb.py\", line 1193, in structured_traceback\n",
      "    tb_offset)\n",
      "  File \"C:\\ProgramData\\Anaconda3\\envs\\tf\\lib\\site-packages\\IPython\\core\\ultratb.py\", line 1150, in format_exception_as_a_whole\n",
      "    last_unique, recursion_repeat = find_recursion(orig_etype, evalue, records)\n",
      "  File \"C:\\ProgramData\\Anaconda3\\envs\\tf\\lib\\site-packages\\IPython\\core\\ultratb.py\", line 451, in find_recursion\n",
      "    return len(records), 0\n",
      "TypeError: object of type 'NoneType' has no len()\n",
      "\n",
      "During handling of the above exception, another exception occurred:\n",
      "\n",
      "Traceback (most recent call last):\n",
      "  File \"C:\\ProgramData\\Anaconda3\\envs\\tf\\lib\\site-packages\\IPython\\core\\interactiveshell.py\", line 2044, in showtraceback\n",
      "    stb = value._render_traceback_()\n",
      "AttributeError: 'TypeError' object has no attribute '_render_traceback_'\n",
      "\n",
      "During handling of the above exception, another exception occurred:\n",
      "\n",
      "Traceback (most recent call last):\n",
      "  File \"C:\\ProgramData\\Anaconda3\\envs\\tf\\lib\\site-packages\\IPython\\core\\ultratb.py\", line 1169, in get_records\n",
      "    return _fixed_getinnerframes(etb, number_of_lines_of_context, tb_offset)\n",
      "  File \"C:\\ProgramData\\Anaconda3\\envs\\tf\\lib\\site-packages\\IPython\\core\\ultratb.py\", line 316, in wrapped\n",
      "    return f(*args, **kwargs)\n",
      "  File \"C:\\ProgramData\\Anaconda3\\envs\\tf\\lib\\site-packages\\IPython\\core\\ultratb.py\", line 350, in _fixed_getinnerframes\n",
      "    records = fix_frame_records_filenames(inspect.getinnerframes(etb, context))\n",
      "  File \"C:\\ProgramData\\Anaconda3\\envs\\tf\\lib\\inspect.py\", line 1500, in getinnerframes\n",
      "    frameinfo = (tb.tb_frame,) + getframeinfo(tb, context)\n",
      "  File \"C:\\ProgramData\\Anaconda3\\envs\\tf\\lib\\inspect.py\", line 1458, in getframeinfo\n",
      "    filename = getsourcefile(frame) or getfile(frame)\n",
      "  File \"C:\\ProgramData\\Anaconda3\\envs\\tf\\lib\\inspect.py\", line 696, in getsourcefile\n",
      "    if getattr(getmodule(object, filename), '__loader__', None) is not None:\n",
      "  File \"C:\\ProgramData\\Anaconda3\\envs\\tf\\lib\\inspect.py\", line 733, in getmodule\n",
      "    if ismodule(module) and hasattr(module, '__file__'):\n",
      "  File \"C:\\ProgramData\\Anaconda3\\envs\\tf\\lib\\site-packages\\tensorflow\\__init__.py\", line 50, in __getattr__\n",
      "    module = self._load()\n",
      "  File \"C:\\ProgramData\\Anaconda3\\envs\\tf\\lib\\site-packages\\tensorflow\\__init__.py\", line 44, in _load\n",
      "    module = _importlib.import_module(self.__name__)\n",
      "  File \"C:\\ProgramData\\Anaconda3\\envs\\tf\\lib\\importlib\\__init__.py\", line 127, in import_module\n",
      "    return _bootstrap._gcd_import(name[level:], package, level)\n",
      "  File \"<frozen importlib._bootstrap>\", line 1006, in _gcd_import\n",
      "  File \"<frozen importlib._bootstrap>\", line 983, in _find_and_load\n",
      "  File \"<frozen importlib._bootstrap>\", line 965, in _find_and_load_unlocked\n",
      "ModuleNotFoundError: No module named 'tensorflow_core._api'\n",
      "Traceback (most recent call last):\n",
      "  File \"C:\\ProgramData\\Anaconda3\\envs\\tf\\lib\\site-packages\\IPython\\core\\interactiveshell.py\", line 3417, in run_code\n",
      "    exec(code_obj, self.user_global_ns, self.user_ns)\n",
      "  File \"<ipython-input-1-64156d691fe5>\", line 1, in <module>\n",
      "    import tensorflow as tf\n",
      "  File \"C:\\ProgramData\\Anaconda3\\envs\\tf\\lib\\site-packages\\tensorflow\\__init__.py\", line 102, in <module>\n",
      "    from tensorflow.python.util import deprecation_wrapper as _deprecation\n",
      "  File \"C:\\ProgramData\\Anaconda3\\envs\\tf\\lib\\site-packages\\tensorflow_core\\python\\util\\deprecation_wrapper.py\", line 25, in <module>\n",
      "    from tensorflow.python.util import module_wrapper\n",
      "  File \"C:\\ProgramData\\Anaconda3\\envs\\tf\\lib\\site-packages\\tensorflow_core\\python\\util\\module_wrapper.py\", line 25, in <module>\n",
      "    from tensorflow.python.platform import tf_logging as logging\n",
      "  File \"C:\\ProgramData\\Anaconda3\\envs\\tf\\lib\\site-packages\\tensorflow_core\\python\\platform\\tf_logging.py\", line 38, in <module>\n",
      "    from tensorflow.python.util.tf_export import tf_export\n",
      "  File \"C:\\ProgramData\\Anaconda3\\envs\\tf\\lib\\site-packages\\tensorflow_core\\python\\util\\tf_export.py\", line 48, in <module>\n",
      "    from tensorflow.python.util import tf_decorator\n",
      "  File \"C:\\ProgramData\\Anaconda3\\envs\\tf\\lib\\site-packages\\tensorflow_core\\python\\util\\tf_decorator.py\", line 64, in <module>\n",
      "    from tensorflow.python.util import tf_stack\n",
      "  File \"C:\\ProgramData\\Anaconda3\\envs\\tf\\lib\\site-packages\\tensorflow_core\\python\\util\\tf_stack.py\", line 29, in <module>\n",
      "    from tensorflow.python import _tf_stack\n",
      "ImportError: cannot import name '_tf_stack' from 'tensorflow_core.python' (unknown location)\n",
      "\n",
      "During handling of the above exception, another exception occurred:\n",
      "\n",
      "Traceback (most recent call last):\n",
      "  File \"C:\\ProgramData\\Anaconda3\\envs\\tf\\lib\\site-packages\\IPython\\core\\interactiveshell.py\", line 2044, in showtraceback\n",
      "    stb = value._render_traceback_()\n",
      "AttributeError: 'ImportError' object has no attribute '_render_traceback_'\n",
      "\n",
      "During handling of the above exception, another exception occurred:\n",
      "\n",
      "Traceback (most recent call last):\n",
      "  File \"C:\\ProgramData\\Anaconda3\\envs\\tf\\lib\\site-packages\\IPython\\core\\interactiveshell.py\", line 3337, in run_ast_nodes\n",
      "    if (await self.run_code(code, result,  async_=asy)):\n",
      "  File \"C:\\ProgramData\\Anaconda3\\envs\\tf\\lib\\site-packages\\IPython\\core\\interactiveshell.py\", line 3434, in run_code\n",
      "    self.showtraceback(running_compiled_code=True)\n",
      "  File \"C:\\ProgramData\\Anaconda3\\envs\\tf\\lib\\site-packages\\IPython\\core\\interactiveshell.py\", line 2047, in showtraceback\n",
      "    value, tb, tb_offset=tb_offset)\n",
      "  File \"C:\\ProgramData\\Anaconda3\\envs\\tf\\lib\\site-packages\\IPython\\core\\ultratb.py\", line 1436, in structured_traceback\n",
      "    self, etype, value, tb, tb_offset, number_of_lines_of_context)\n",
      "  File \"C:\\ProgramData\\Anaconda3\\envs\\tf\\lib\\site-packages\\IPython\\core\\ultratb.py\", line 1336, in structured_traceback\n",
      "    self, etype, value, tb, tb_offset, number_of_lines_of_context\n",
      "  File \"C:\\ProgramData\\Anaconda3\\envs\\tf\\lib\\site-packages\\IPython\\core\\ultratb.py\", line 1193, in structured_traceback\n",
      "    tb_offset)\n",
      "  File \"C:\\ProgramData\\Anaconda3\\envs\\tf\\lib\\site-packages\\IPython\\core\\ultratb.py\", line 1150, in format_exception_as_a_whole\n",
      "    last_unique, recursion_repeat = find_recursion(orig_etype, evalue, records)\n",
      "  File \"C:\\ProgramData\\Anaconda3\\envs\\tf\\lib\\site-packages\\IPython\\core\\ultratb.py\", line 451, in find_recursion\n",
      "    return len(records), 0\n",
      "TypeError: object of type 'NoneType' has no len()\n",
      "\n",
      "During handling of the above exception, another exception occurred:\n",
      "\n",
      "Traceback (most recent call last):\n",
      "  File \"C:\\ProgramData\\Anaconda3\\envs\\tf\\lib\\site-packages\\IPython\\core\\interactiveshell.py\", line 2044, in showtraceback\n",
      "    stb = value._render_traceback_()\n",
      "AttributeError: 'TypeError' object has no attribute '_render_traceback_'\n",
      "\n",
      "During handling of the above exception, another exception occurred:\n",
      "\n",
      "Traceback (most recent call last):\n",
      "  File \"C:\\ProgramData\\Anaconda3\\envs\\tf\\lib\\site-packages\\IPython\\core\\interactiveshell.py\", line 2922, in _run_cell\n",
      "    return runner(coro)\n",
      "  File \"C:\\ProgramData\\Anaconda3\\envs\\tf\\lib\\site-packages\\IPython\\core\\async_helpers.py\", line 68, in _pseudo_sync_runner\n",
      "    coro.send(None)\n",
      "  File \"C:\\ProgramData\\Anaconda3\\envs\\tf\\lib\\site-packages\\IPython\\core\\interactiveshell.py\", line 3146, in run_cell_async\n",
      "    interactivity=interactivity, compiler=compiler, result=result)\n",
      "  File \"C:\\ProgramData\\Anaconda3\\envs\\tf\\lib\\site-packages\\IPython\\core\\interactiveshell.py\", line 3356, in run_ast_nodes\n",
      "    self.showtraceback()\n",
      "  File \"C:\\ProgramData\\Anaconda3\\envs\\tf\\lib\\site-packages\\IPython\\core\\interactiveshell.py\", line 2047, in showtraceback\n",
      "    value, tb, tb_offset=tb_offset)\n",
      "  File \"C:\\ProgramData\\Anaconda3\\envs\\tf\\lib\\site-packages\\IPython\\core\\ultratb.py\", line 1436, in structured_traceback\n",
      "    self, etype, value, tb, tb_offset, number_of_lines_of_context)\n",
      "  File \"C:\\ProgramData\\Anaconda3\\envs\\tf\\lib\\site-packages\\IPython\\core\\ultratb.py\", line 1336, in structured_traceback\n",
      "    self, etype, value, tb, tb_offset, number_of_lines_of_context\n",
      "  File \"C:\\ProgramData\\Anaconda3\\envs\\tf\\lib\\site-packages\\IPython\\core\\ultratb.py\", line 1211, in structured_traceback\n",
      "    chained_exceptions_tb_offset)\n",
      "  File \"C:\\ProgramData\\Anaconda3\\envs\\tf\\lib\\site-packages\\IPython\\core\\ultratb.py\", line 1150, in format_exception_as_a_whole\n",
      "    last_unique, recursion_repeat = find_recursion(orig_etype, evalue, records)\n",
      "  File \"C:\\ProgramData\\Anaconda3\\envs\\tf\\lib\\site-packages\\IPython\\core\\ultratb.py\", line 451, in find_recursion\n",
      "    return len(records), 0\n",
      "TypeError: object of type 'NoneType' has no len()\n",
      "\n",
      "During handling of the above exception, another exception occurred:\n",
      "\n",
      "Traceback (most recent call last):\n",
      "  File \"C:\\ProgramData\\Anaconda3\\envs\\tf\\lib\\site-packages\\IPython\\core\\interactiveshell.py\", line 2044, in showtraceback\n",
      "    stb = value._render_traceback_()\n",
      "AttributeError: 'TypeError' object has no attribute '_render_traceback_'\n",
      "\n",
      "During handling of the above exception, another exception occurred:\n",
      "\n",
      "Traceback (most recent call last):\n",
      "  File \"C:\\ProgramData\\Anaconda3\\envs\\tf\\lib\\site-packages\\IPython\\core\\ultratb.py\", line 1169, in get_records\n",
      "    return _fixed_getinnerframes(etb, number_of_lines_of_context, tb_offset)\n",
      "  File \"C:\\ProgramData\\Anaconda3\\envs\\tf\\lib\\site-packages\\IPython\\core\\ultratb.py\", line 316, in wrapped\n",
      "    return f(*args, **kwargs)\n",
      "  File \"C:\\ProgramData\\Anaconda3\\envs\\tf\\lib\\site-packages\\IPython\\core\\ultratb.py\", line 350, in _fixed_getinnerframes\n",
      "    records = fix_frame_records_filenames(inspect.getinnerframes(etb, context))\n",
      "  File \"C:\\ProgramData\\Anaconda3\\envs\\tf\\lib\\inspect.py\", line 1500, in getinnerframes\n",
      "    frameinfo = (tb.tb_frame,) + getframeinfo(tb, context)\n",
      "  File \"C:\\ProgramData\\Anaconda3\\envs\\tf\\lib\\inspect.py\", line 1458, in getframeinfo\n",
      "    filename = getsourcefile(frame) or getfile(frame)\n",
      "  File \"C:\\ProgramData\\Anaconda3\\envs\\tf\\lib\\inspect.py\", line 696, in getsourcefile\n",
      "    if getattr(getmodule(object, filename), '__loader__', None) is not None:\n",
      "  File \"C:\\ProgramData\\Anaconda3\\envs\\tf\\lib\\inspect.py\", line 733, in getmodule\n",
      "    if ismodule(module) and hasattr(module, '__file__'):\n",
      "  File \"C:\\ProgramData\\Anaconda3\\envs\\tf\\lib\\site-packages\\tensorflow\\__init__.py\", line 50, in __getattr__\n",
      "    module = self._load()\n",
      "  File \"C:\\ProgramData\\Anaconda3\\envs\\tf\\lib\\site-packages\\tensorflow\\__init__.py\", line 44, in _load\n",
      "    module = _importlib.import_module(self.__name__)\n",
      "  File \"C:\\ProgramData\\Anaconda3\\envs\\tf\\lib\\importlib\\__init__.py\", line 127, in import_module\n",
      "    return _bootstrap._gcd_import(name[level:], package, level)\n",
      "  File \"<frozen importlib._bootstrap>\", line 1006, in _gcd_import\n",
      "  File \"<frozen importlib._bootstrap>\", line 983, in _find_and_load\n",
      "  File \"<frozen importlib._bootstrap>\", line 965, in _find_and_load_unlocked\n",
      "ModuleNotFoundError: No module named 'tensorflow_core._api'\n",
      "ERROR! Session/line number was not unique in database. History logging moved to new session 1028\n"
     ]
    }
   ],
   "source": [
    "import tensorflow as tf"
   ]
  },
  {
   "cell_type": "markdown",
   "metadata": {},
   "source": [
    "## Understanding the Approach\n",
    "\n",
    "This appraoch is taken from the popular [FaceNet](https://arxiv.org/abs/1503.03832) paper.\n",
    "\n",
    "We have a CNN model called `EmbeddingModel`:\n",
    "\n",
    "![CNN](assets/CNN.png)\n",
    "\n",
    "We use three images for each training example:\n",
    "1. `person1_image1.jpg` (Anchor Example, represented below in green)\n",
    "2. `person1_image2.jpg` (Positive Example, in blue)\n",
    "3. `person2_image1.jpg` (Negative Example, in red).\n",
    "\n",
    "![Embeddings](assets/embeddings.png)\n",
    "\n",
    "\n",
    "## Siamese Network\n",
    "\n",
    "All the three images of an example pass through the model, and we get the three Embeddings: One for the Anchor Example, one for the Positive Example, and one for the Negative Example.\n",
    "\n",
    "![Siamese Network](assets/siamese.png)\n",
    "\n",
    "The three instances of the `EmbeddingModel` shown above are not different instances. It's the same, shared model instance - i.e. the parameters are shared, and are updated for all the three paths simultaneously."
   ]
  },
  {
   "cell_type": "markdown",
   "metadata": {},
   "source": [
    "# Task 2: Importing the Data"
   ]
  },
  {
   "cell_type": "code",
   "execution_count": null,
   "metadata": {},
   "outputs": [],
   "source": [
    "(x_train, y_train), (x_test, y_test) = tf.keras.datasets.mnist.load_data()\n",
    "print(x_train.shape)"
   ]
  },
  {
   "cell_type": "code",
   "execution_count": null,
   "metadata": {},
   "outputs": [],
   "source": [
    "x_train = np.reshape(x_train, (x_train.shape[0], 784))/255.\n",
    "x_test = np.reshape(x_test, (x_test.shape[0], 784))/255.\n",
    "print(x_train.shape)"
   ]
  },
  {
   "cell_type": "markdown",
   "metadata": {},
   "source": [
    "# Task 3: Plotting Examples"
   ]
  },
  {
   "cell_type": "code",
   "execution_count": null,
   "metadata": {},
   "outputs": [],
   "source": [
    "def plot_triplets(examples):\n",
    "    plt.figure(figsize=(6, 2))\n",
    "    for i in range(3):\n",
    "        plt.subplot(1, 3, 1 + i)\n",
    "        plt.imshow(np.reshape(examples[i], (28, 28)), cmap='binary')\n",
    "        plt.xticks([])\n",
    "        plt.yticks([])\n",
    "    plt.show()"
   ]
  },
  {
   "cell_type": "code",
   "execution_count": null,
   "metadata": {},
   "outputs": [],
   "source": [
    "plot_triplets([x_train[0], x_train[1], x_train[2]])"
   ]
  },
  {
   "cell_type": "markdown",
   "metadata": {},
   "source": [
    "# Task 4: A Batch of Triplets"
   ]
  },
  {
   "cell_type": "code",
   "execution_count": null,
   "metadata": {},
   "outputs": [],
   "source": [
    "def create_batch(batch_size=256):\n",
    "    x_anchors = np.zeros((batch_size, 784))\n",
    "    x_positives = np.zeros((batch_size, 784))\n",
    "    x_negatives = np.zeros((batch_size, 784))\n",
    "    \n",
    "    for i in range(0, batch_size):\n",
    "        # We need to find an anchor, a positive example and a negative example\n",
    "        random_index = random.randint(0, x_train.shape[0] - 1)\n",
    "        x_anchor = x_train[random_index]\n",
    "        y = y_train[random_index]\n",
    "        \n",
    "        indices_for_pos = np.squeeze(np.where(y_train == y))\n",
    "        indices_for_neg = np.squeeze(np.where(y_train != y))\n",
    "        \n",
    "        x_positive = x_train[indices_for_pos[random.randint(0, len(indices_for_pos) - 1)]]\n",
    "        x_negative = x_train[indices_for_neg[random.randint(0, len(indices_for_neg) - 1)]]\n",
    "        \n",
    "        x_anchors[i] = x_anchor\n",
    "        x_positives[i] = x_positive\n",
    "        x_negatives[i] = x_negative\n",
    "        \n",
    "    return [x_anchors, x_positives, x_negatives]"
   ]
  },
  {
   "cell_type": "code",
   "execution_count": null,
   "metadata": {},
   "outputs": [],
   "source": [
    "examples = create_batch(1)\n",
    "plot_triplets(examples)"
   ]
  },
  {
   "cell_type": "markdown",
   "metadata": {},
   "source": [
    "# Task 5: Embedding Model"
   ]
  },
  {
   "cell_type": "code",
   "execution_count": null,
   "metadata": {},
   "outputs": [],
   "source": [
    "emb_size = 64\n",
    "\n",
    "embedding_model = tf.keras.models.Sequential([\n",
    "    tf.keras.layers.Dense(64, activation='relu', input_shape=(784,)),\n",
    "    tf.keras.layers.Dense(emb_size, activation='sigmoid')\n",
    "])\n",
    "\n",
    "embedding_model.summary()"
   ]
  },
  {
   "cell_type": "code",
   "execution_count": null,
   "metadata": {},
   "outputs": [],
   "source": [
    "example = np.expand_dims(x_train[0], axis=0)\n",
    "example_emb = embedding_model.predict(example)[0]\n",
    "\n",
    "print(example_emb)"
   ]
  },
  {
   "cell_type": "markdown",
   "metadata": {},
   "source": [
    "# Task 6: Siamese Network"
   ]
  },
  {
   "cell_type": "code",
   "execution_count": null,
   "metadata": {},
   "outputs": [],
   "source": [
    "input_anchor = tf.keras.layers.Input(shape=(784,))\n",
    "input_positive = tf.keras.layers.Input(shape=(784,))\n",
    "input_negative = tf.keras.layers.Input(shape=(784,))\n",
    "\n",
    "embedding_anchor = embedding_model(input_anchor)\n",
    "embedding_positive = embedding_model(input_positive)\n",
    "embedding_negative = embedding_model(input_negative)\n",
    "\n",
    "output = tf.keras.layers.concatenate([embedding_anchor, embedding_positive, embedding_negative], axis=1)\n",
    "\n",
    "net = tf.keras.models.Model([input_anchor, input_positive, input_negative], output)\n",
    "net.summary()"
   ]
  },
  {
   "cell_type": "markdown",
   "metadata": {},
   "source": [
    "# Task 7: Triplet Loss\n",
    "\n",
    "A loss function that tries to pull the Embeddings of Anchor and Positive Examples closer, and tries to push the Embeddings of Anchor and Negative Examples away from each other.\n",
    "\n",
    "Root mean square difference between Anchor and Positive examples in a batch of N images is:\n",
    "$\n",
    "\\begin{equation}\n",
    "d_p = \\sqrt{\\frac{\\sum_{i=0}^{N-1}(f(a_i) - f(p_i))^2}{N}}\n",
    "\\end{equation}\n",
    "$\n",
    "\n",
    "Root mean square difference between Anchor and Negative examples in a batch of N images is:\n",
    "$\n",
    "\\begin{equation}\n",
    "d_n = \\sqrt{\\frac{\\sum_{i=0}^{N-1}(f(a_i) - f(n_i))^2}{N}}\n",
    "\\end{equation}\n",
    "$\n",
    "\n",
    "For each example, we want:\n",
    "$\n",
    "\\begin{equation}\n",
    "d_p \\leq d_n\n",
    "\\end{equation}\n",
    "$\n",
    "\n",
    "Therefore,\n",
    "$\n",
    "\\begin{equation}\n",
    "d_p - d_n \\leq 0\n",
    "\\end{equation}\n",
    "$\n",
    "\n",
    "This condition is quite easily satisfied during the training.\n",
    "\n",
    "We will make it non-trivial by adding a margin (alpha):\n",
    "$\n",
    "\\begin{equation}\n",
    "d_p - d_n + \\alpha \\leq 0\n",
    "\\end{equation}\n",
    "$\n",
    "\n",
    "Given the condition above, the Triplet Loss L is defined as:\n",
    "$\n",
    "\\begin{equation}\n",
    "L = max(d_p - d_n + \\alpha, 0)\n",
    "\\end{equation}\n",
    "$"
   ]
  },
  {
   "cell_type": "code",
   "execution_count": null,
   "metadata": {},
   "outputs": [],
   "source": [
    "alpha = 0.2\n",
    "\n",
    "def triplet_loss(y_true, y_pred):\n",
    "    anchor, positive, negative = y_pred[:,:emb_size], y_pred[:,emb_size:2*emb_size], y_pred[:,2*emb_size:]\n",
    "    positive_dist = tf.reduce_mean(tf.square(anchor - positive), axis=1)\n",
    "    negative_dist = tf.reduce_mean(tf.square(anchor - negative), axis=1)\n",
    "    return tf.maximum(positive_dist - negative_dist + alpha, 0.)"
   ]
  },
  {
   "cell_type": "markdown",
   "metadata": {},
   "source": [
    "# Task 8: Data Generator"
   ]
  },
  {
   "cell_type": "code",
   "execution_count": null,
   "metadata": {},
   "outputs": [],
   "source": [
    "def data_generator(batch_size=256):\n",
    "    while True:\n",
    "        x = create_batch(batch_size)\n",
    "        y = np.zeros((batch_size, 3*emb_size))\n",
    "        yield x, y"
   ]
  },
  {
   "cell_type": "markdown",
   "metadata": {},
   "source": [
    "# Task 9: Model Training"
   ]
  },
  {
   "cell_type": "code",
   "execution_count": null,
   "metadata": {},
   "outputs": [],
   "source": [
    "batch_size = 2048\n",
    "epochs = 10\n",
    "steps_per_epoch = int(x_train.shape[0]/batch_size)\n",
    "\n",
    "net.compile(loss=triplet_loss, optimizer='adam')\n",
    "\n",
    "_ = net.fit(\n",
    "    data_generator(batch_size),\n",
    "    steps_per_epoch=steps_per_epoch,\n",
    "    epochs=epochs, verbose=False,\n",
    "    callbacks=[\n",
    "        PCAPlotter(\n",
    "            plt, embedding_model,\n",
    "            x_test[:1000], y_test[:1000]\n",
    "        )]\n",
    ")"
   ]
  },
  {
   "cell_type": "code",
   "execution_count": null,
   "metadata": {},
   "outputs": [],
   "source": []
  }
 ],
 "metadata": {
  "kernelspec": {
   "display_name": "Python 3",
   "language": "python",
   "name": "python3"
  },
  "language_info": {
   "codemirror_mode": {
    "name": "ipython",
    "version": 3
   },
   "file_extension": ".py",
   "mimetype": "text/x-python",
   "name": "python",
   "nbconvert_exporter": "python",
   "pygments_lexer": "ipython3",
   "version": "3.7.1"
  }
 },
 "nbformat": 4,
 "nbformat_minor": 2
}
